Workbook

Sheet Commissions
A1: Number | B1: PPC125 | C1: [12.5} | D1: Charles | E1: Harry | F1: LightHouse | H1: PPC125 | I1: [12.22} | J1: Charles | K1: Harry | L1: LightHouse | O1: Charles | P1: Harry | Q1: LightHouse
A2: 593-43-4445 | B2: =VLOOKUP(A2,'12.5'!A:B,2,FALSE) -> -738.46 | C2: {=_xlfn.IFS( B2=-738.46,"Plan 1600", B2=-646.15,"Plan 1400", B2=-553.85,"Plan 1200", B2=-461.54,"Plan 1000" )} -> Plan 1600 | D2: {=_xlfn.SWITCH($C2,"Plan 1600",15*12/26,"Plan 1400",10*12/26,"Plan 1200",5*12/26,"Plan 1000",1.5*12/26,"")} -> 6.9230769 | E2: {=_xlfn.SWITCH($C2,"Plan 1600",97*12/26,"Plan 1400",78*12/26,"Plan 1200",60*12/26,"Plan 1000",25*12/26,"")} -> 44.769231 | F2: {=_xlfn.SWITCH($C2,"Plan 1600",25*12/26,"Plan 1400",20*12/26,"Plan 1200",15*12/26,"Plan 1000",2*12/26,"")} -> 11.538462 | H2: =VLOOKUP(A2,'12.22'!A:B,2,FALSE) -> -738.46 | I2: {=_xlfn.IFS( H2=-738.46,"Plan 1600", H2=-646.15,"Plan 1400", H2=-553.85,"Plan 1200", H2=-461.54,"Plan 1000" )} -> Plan 1600 | J2: {=_xlfn.SWITCH($I2,"Plan 1600",15*12/26,"Plan 1400",10*12/26,"Plan 1200",5*12/26,"Plan 1000",1.5*12/26,"")} -> 6.9230769 | K2: {=_xlfn.SWITCH($I2,"Plan 1600",97*12/26,"Plan 1400",78*12/26,"Plan 1200",60*12/26,"Plan 1000",25*12/26,"")} -> 44.769231 | L2: {=_xlfn.SWITCH($I2,"Plan 1600",25*12/26,"Plan 1400",20*12/26,"Plan 1200",15*12/26,"Plan 1000",2*12/26,"")} -> 11.538462 | N2: Total | O2: =D48+J48 -> 204 | P2: =E48+K48 -> 1923.2308 | Q2: =F48+L48 -> 374.30769
A3: 263-79-8264 | B3: =VLOOKUP(A3,'12.5'!A:B,2,FALSE) -> -738.46 | C3: {=_xlfn.IFS( B3=-738.46,"Plan 1600", B3=-646.15,"Plan 1400", B3=-553.85,"Plan 1200", B3=-461.54,"Plan 1000" )} -> Plan 1600 | D3: {=_xlfn.SWITCH($C3,"Plan 1600",15*12/26,"Plan 1400",10*12/26,"Plan 1200",5*12/26,"Plan 1000",1.5*12/26,"")} -> 6.9230769 | E3: {=_xlfn.SWITCH($C3,"Plan 1600",97*12/26,"Plan 1400",78*12/26,"Plan 1200",60*12/26,"Plan 1000",25*12/26,"")} -> 44.769231 | F3: {=_xlfn.SWITCH($C3,"Plan 1600",25*12/26,"Plan 1400",20*12/26,"Plan 1200",15*12/26,"Plan 1000",2*12/26,"")} -> 11.538462 | H3: =VLOOKUP(A3,'12.22'!A:B,2,FALSE) -> -738.46 | I3: {=_xlfn.IFS( H3=-738.46,"Plan 1600", H3=-646.15,"Plan 1400", H3=-553.85,"Plan 1200", H3=-461.54,"Plan 1000" )} -> Plan 1600 | J3: {=_xlfn.SWITCH($I3,"Plan 1600",15*12/26,"Plan 1400",10*12/26,"Plan 1200",5*12/26,"Plan 1000",1.5*12/26,"")} -> 6.9230769 | K3: {=_xlfn.SWITCH($I3,"Plan 1600",97*12/26,"Plan 1400",78*12/26,"Plan 1200",60*12/26,"Plan 1000",25*12/26,"")} -> 44.769231 | L3: {=_xlfn.SWITCH($I3,"Plan 1600",25*12/26,"Plan 1400",20*12/26,"Plan 1200",15*12/26,"Plan 1000",2*12/26,"")} -> 11.538462
A4: 438-67-6419 | B4: =VLOOKUP(A4,'12.5'!A:B,2,FALSE) -> -738.46 | C4: {=_xlfn.IFS( B4=-738.46,"Plan 1600", B4=-646.15,"Plan 1400", B4=-553.85,"Plan 1200", B4=-461.54,"Plan 1000" )} -> Plan 1600 | D4: {=_xlfn.SWITCH($C4,"Plan 1600",15*12/26,"Plan 1400",10*12/26,"Plan 1200",5*12/26,"Plan 1000",1.5*12/26,"")} -> 6.9230769 | E4: {=_xlfn.SWITCH($C4,"Plan 1600",97*12/26,"Plan 1400",78*12/26,"Plan 1200",60*12/26,"Plan 1000",25*12/26,"")} -> 44.769231 | F4: {=_xlfn.SWITCH($C4,"Plan 1600",25*12/26,"Plan 1400",20*12/26,"Plan 1200",15*12/26,"Plan 1000",2*12/26,"")} -> 11.538462 | H4: =VLOOKUP(A4,'12.22'!A:B,2,FALSE) -> -738.46 | I4: {=_xlfn.IFS( H4=-738.46,"Plan 1600", H4=-646.15,"Plan 1400", H4=-553.85,"Plan 1200", H4=-461.54,"Plan 1000" )} -> Plan 1600 | J4: {=_xlfn.SWITCH($I4,"Plan 1600",15*12/26,"Plan 1400",10*12/26,"Plan 1200",5*12/26,"Plan 1000",1.5*12/26,"")} -> 6.9230769 | K4: {=_xlfn.SWITCH($I4,"Plan 1600",97*12/26,"Plan 1400",78*12/26,"Plan 1200",60*12/26,"Plan 1000",25*12/26,"")} -> 44.769231 | L4: {=_xlfn.SWITCH($I4,"Plan 1600",25*12/26,"Plan 1400",20*12/26,"Plan 1200",15*12/26,"Plan 1000",2*12/26,"")} -> 11.538462 | P4: Agent 1 | Q4: Agent 2
A5: 267-27-8279 | B5: =VLOOKUP(A5,'12.5'!A:B,2,FALSE) -> -738.46 | C5: {=_xlfn.IFS( B5=-738.46,"Plan 1600", B5=-646.15,"Plan 1400", B5=-553.85,"Plan 1200", B5=-461.54,"Plan 1000" )} -> Plan 1600 | D5: {=_xlfn.SWITCH($C5,"Plan 1600",15*12/26,"Plan 1400",10*12/26,"Plan 1200",5*12/26,"Plan 1000",1.5*12/26,"")} -> 6.9230769 | E5: {=_xlfn.SWITCH($C5,"Plan 1600",97*12/26,"Plan 1400",78*12/26,"Plan 1200",60*12/26,"Plan 1000",25*12/26,"")} -> 44.769231 | F5: {=_xlfn.SWITCH($C5,"Plan 1600",25*12/26,"Plan 1400",20*12/26,"Plan 1200",15*12/26,"Plan 1000",2*12/26,"")} -> 11.538462 | H5: =VLOOKUP(A5,'12.22'!A:B,2,FALSE) -> -738.46 | I5: {=_xlfn.IFS( H5=-738.46,"Plan 1600", H5=-646.15,"Plan 1400", H5=-553.85,"Plan 1200", H5=-461.54,"Plan 1000" )} -> Plan 1600 | J5: {=_xlfn.SWITCH($I5,"Plan 1600",15*12/26,"Plan 1400",10*12/26,"Plan 1200",5*12/26,"Plan 1000",1.5*12/26,"")} -> 6.9230769 | K5: {=_xlfn.SWITCH($I5,"Plan 1600",97*12/26,"Plan 1400",78*12/26,"Plan 1200",60*12/26,"Plan 1000",25*12/26,"")} -> 44.769231 | L5: {=_xlfn.SWITCH($I5,"Plan 1600",25*12/26,"Plan 1400",20*12/26,"Plan 1200",15*12/26,"Plan 1000",2*12/26,"")} -> 11.538462 | N5: Plan 1000 Total | O5: {=SUMPRODUCT(--( (ISNUMBER(SEARCH("Plan 1000",C2:C47))+ ISNUMBER(SEARCH("Plan 1000",I2:I47)))>0 ))} -> 30 | P5: =O5*5 -> 150 | Q5: =O5*5 -> 150
A6: 278-72-1895 | B6: =VLOOKUP(A6,'12.5'!A:B,2,FALSE) -> -738.46 | C6: {=_xlfn.IFS( B6=-738.46,"Plan 1600", B6=-646.15,"Plan 1400", B6=-553.85,"Plan 1200", B6=-461.54,"Plan 1000" )} -> Plan 1600 | D6: {=_xlfn.SWITCH($C6,"Plan 1600",15*12/26,"Plan 1400",10*12/26,"Plan 1200",5*12/26,"Plan 1000",1.5*12/26,"")} -> 6.9230769 | E6: {=_xlfn.SWITCH($C6,"Plan 1600",97*12/26,"Plan 1400",78*12/26,"Plan 1200",60*12/26,"Plan 1000",25*12/26,"")} -> 44.769231 | F6: {=_xlfn.SWITCH($C6,"Plan 1600",25*12/26,"Plan 1400",20*12/26,"Plan 1200",15*12/26,"Plan 1000",2*12/26,"")} -> 11.538462 | H6: =VLOOKUP(A6,'12.22'!A:B,2,FALSE) -> -738.46 | I6: {=_xlfn.IFS( H6=-738.46,"Plan 1600", H6=-646.15,"Plan 1400", H6=-553.85,"Plan 1200", H6=-461.54,"Plan 1000" )} -> Plan 1600 | J6: {=_xlfn.SWITCH($I6,"Plan 1600",15*12/26,"Plan 1400",10*12/26,"Plan 1200",5*12/26,"Plan 1000",1.5*12/26,"")} -> 6.9230769 | K6: {=_xlfn.SWITCH($I6,"Plan 1600",97*12/26,"Plan 1400",78*12/26,"Plan 1200",60*12/26,"Plan 1000",25*12/26,"")} -> 44.769231 | L6: {=_xlfn.SWITCH($I6,"Plan 1600",25*12/26,"Plan 1400",20*12/26,"Plan 1200",15*12/26,"Plan 1000",2*12/26,"")} -> 11.538462 | N6: Other Plans Total | O6: {=SUMPRODUCT(--( (ISNUMBER(SEARCH("Plan 1000",C2:C47))+ISNUMBER(SEARCH("Plan 1000",I2:I47))=0)* (ISNUMBER(SEARCH("Plan 1200",C2:C47))+ISNUMBER(SEARCH("Plan 1400",C2:C47))+ISNUMBER(SEARCH("Plan 1600",C2:C47))>0)* (ISNUMBER(SEARCH("Plan 1200",I2:I47))+ISNUMBER(SEARCH("Plan 1400",I2:I47))+ISNUMBER(SEARCH("Plan 1600",I2:I47))>0) ))} -> 16 | P6: =O6*7.5 -> 120 | Q6: =O6*7.5 -> 120
A7: 584-81-8792 | B7: =VLOOKUP(A7,'12.5'!A:B,2,FALSE) -> -646.15 | C7: {=_xlfn.IFS( B7=-738.46,"Plan 1600", B7=-646.15,"Plan 1400", B7=-553.85,"Plan 1200", B7=-461.54,"Plan 1000" )} -> Plan 1400 | D7: {=_xlfn.SWITCH($C7,"Plan 1600",15*12/26,"Plan 1400",10*12/26,"Plan 1200",5*12/26,"Plan 1000",1.5*12/26,"")} -> 4.6153846 | E7: {=_xlfn.SWITCH($C7,"Plan 1600",97*12/26,"Plan 1400",78*12/26,"Plan 1200",60*12/26,"Plan 1000",25*12/26,"")} -> 36 | F7: {=_xlfn.SWITCH($C7,"Plan 1600",25*12/26,"Plan 1400",20*12/26,"Plan 1200",15*12/26,"Plan 1000",2*12/26,"")} -> 9.2307692 | H7: =VLOOKUP(A7,'12.22'!A:B,2,FALSE) -> -646.15 | I7: {=_xlfn.IFS( H7=-738.46,"Plan 1600", H7=-646.15,"Plan 1400", H7=-553.85,"Plan 1200", H7=-461.54,"Plan 1000" )} -> Plan 1400 | J7: {=_xlfn.SWITCH($I7,"Plan 1600",15*12/26,"Plan 1400",10*12/26,"Plan 1200",5*12/26,"Plan 1000",1.5*12/26,"")} -> 4.6153846 | K7: {=_xlfn.SWITCH($I7,"Plan 1600",97*12/26,"Plan 1400",78*12/26,"Plan 1200",60*12/26,"Plan 1000",25*12/26,"")} -> 36 | L7: {=_xlfn.SWITCH($I7,"Plan 1600",25*12/26,"Plan 1400",20*12/26,"Plan 1200",15*12/26,"Plan 1000",2*12/26,"")} -> 9.2307692 | P7: =SUM(P5:P6) -> 270 | Q7: =SUM(Q5:Q6) -> 270 | R7: =SUM(P7:Q7) -> 540
A8: 170-81-2820 | B8: =VLOOKUP(A8,'12.5'!A:B,2,FALSE) -> -646.15 | C8: {=_xlfn.IFS( B8=-738.46,"Plan 1600", B8=-646.15,"Plan 1400", B8=-553.85,"Plan 1200", B8=-461.54,"Plan 1000" )} -> Plan 1400 | D8: {=_xlfn.SWITCH($C8,"Plan 1600",15*12/26,"Plan 1400",10*12/26,"Plan 1200",5*12/26,"Plan 1000",1.5*12/26,"")} -> 4.6153846 | E8: {=_xlfn.SWITCH($C8,"Plan 1600",97*12/26,"Plan 1400",78*12/26,"Plan 1200",60*12/26,"Plan 1000",25*12/26,"")} -> 36 | F8: {=_xlfn.SWITCH($C8,"Plan 1600",25*12/26,"Plan 1400",20*12/26,"Plan 1200",15*12/26,"Plan 1000",2*12/26,"")} -> 9.2307692 | H8: =VLOOKUP(A8,'12.22'!A:B,2,FALSE) -> -646.15 | I8: {=_xlfn.IFS( H8=-738.46,"Plan 1600", H8=-646.15,"Plan 1400", H8=-553.85,"Plan 1200", H8=-461.54,"Plan 1000" )} -> Plan 1400 | J8: {=_xlfn.SWITCH($I8,"Plan 1600",15*12/26,"Plan 1400",10*12/26,"Plan 1200",5*12/26,"Plan 1000",1.5*12/26,"")} -> 4.6153846 | K8: {=_xlfn.SWITCH($I8,"Plan 1600",97*12/26,"Plan 1400",78*12/26,"Plan 1200",60*12/26,"Plan 1000",25*12/26,"")} -> 36 | L8: {=_xlfn.SWITCH($I8,"Plan 1600",25*12/26,"Plan 1400",20*12/26,"Plan 1200",15*12/26,"Plan 1000",2*12/26,"")} -> 9.2307692
A9: 883-77-8340 | B9: =VLOOKUP(A9,'12.5'!A:B,2,FALSE) -> -646.15 | C9: {=_xlfn.IFS( B9=-738.46,"Plan 1600", B9=-646.15,"Plan 1400", B9=-553.85,"Plan 1200", B9=-461.54,"Plan 1000" )} -> Plan 1400 | D9: {=_xlfn.SWITCH($C9,"Plan 1600",15*12/26,"Plan 1400",10*12/26,"Plan 1200",5*12/26,"Plan 1000",1.5*12/26,"")} -> 4.6153846 | E9: {=_xlfn.SWITCH($C9,"Plan 1600",97*12/26,"Plan 1400",78*12/26,"Plan 1200",60*12/26,"Plan 1000",25*12/26,"")} -> 36 | F9: {=_xlfn.SWITCH($C9,"Plan 1600",25*12/26,"Plan 1400",20*12/26,"Plan 1200",15*12/26,"Plan 1000",2*12/26,"")} -> 9.2307692 | H9: =VLOOKUP(A9,'12.22'!A:B,2,FALSE) -> -646.15 | I9: {=_xlfn.IFS( H9=-738.46,"Plan 1600", H9=-646.15,"Plan 1400", H9=-553.85,"Plan 1200", H9=-461.54,"Plan 1000" )} -> Plan 1400 | J9: {=_xlfn.SWITCH($I9,"Plan 1600",15*12/26,"Plan 1400",10*12/26,"Plan 1200",5*12/26,"Plan 1000",1.5*12/26,"")} -> 4.6153846 | K9: {=_xlfn.SWITCH($I9,"Plan 1600",97*12/26,"Plan 1400",78*12/26,"Plan 1200",60*12/26,"Plan 1000",25*12/26,"")} -> 36 | L9: {=_xlfn.SWITCH($I9,"Plan 1600",25*12/26,"Plan 1400",20*12/26,"Plan 1200",15*12/26,"Plan 1000",2*12/26,"")} -> 9.2307692
A10: 131-44-2343 | B10: =VLOOKUP(A10,'12.5'!A:B,2,FALSE) -> -646.15 | C10: {=_xlfn.IFS( B10=-738.46,"Plan 1600", B10=-646.15,"Plan 1400", B10=-553.85,"Plan 1200", B10=-461.54,"Plan 1000" )} -> Plan 1400 | D10: {=_xlfn.SWITCH($C10,"Plan 1600",15*12/26,"Plan 1400",10*12/26,"Plan 1200",5*12/26,"Plan 1000",1.5*12/26,"")} -> 4.6153846 | E10: {=_xlfn.SWITCH($C10,"Plan 1600",97*12/26,"Plan 1400",78*12/26,"Plan 1200",60*12/26,"Plan 1000",25*12/26,"")} -> 36 | F10: {=_xlfn.SWITCH($C10,"Plan 1600",25*12/26,"Plan 1400",20*12/26,"Plan 1200",15*12/26,"Plan 1000",2*12/26,"")} -> 9.2307692 | H10: =VLOOKUP(A10,'12.22'!A:B,2,FALSE) -> -738.46 | I10: {=_xlfn.IFS( H10=-738.46,"Plan 1600", H10=-646.15,"Plan 1400", H10=-553.85,"Plan 1200", H10=-461.54,"Plan 1000" )} -> Plan 1600 | J10: {=_xlfn.SWITCH($I10,"Plan 1600",15*12/26,"Plan 1400",10*12/26,"Plan 1200",5*12/26,"Plan 1000",1.5*12/26,"")} -> 6.9230769 | K10: {=_xlfn.SWITCH($I10,"Plan 1600",97*12/26,"Plan 1400",78*12/26,"Plan 1200",60*12/26,"Plan 1000",25*12/26,"")} -> 44.769231 | L10: {=_xlfn.SWITCH($I10,"Plan 1600",25*12/26,"Plan 1400",20*12/26,"Plan 1200",15*12/26,"Plan 1000",2*12/26,"")} -> 11.538462
A11: 593-44-9070 | B11: =VLOOKUP(A11,'12.5'!A:B,2,FALSE) -> -646.15 | C11: {=_xlfn.IFS( B11=-738.46,"Plan 1600", B11=-646.15,"Plan 1400", B11=-553.85,"Plan 1200", B11=-461.54,"Plan 1000" )} -> Plan 1400 | D11: {=_xlfn.SWITCH($C11,"Plan 1600",15*12/26,"Plan 1400",10*12/26,"Plan 1200",5*12/26,"Plan 1000",1.5*12/26,"")} -> 4.6153846 | E11: {=_xlfn.SWITCH($C11,"Plan 1600",97*12/26,"Plan 1400",78*12/26,"Plan 1200",60*12/26,"Plan 1000",25*12/26,"")} -> 36 | F11: {=_xlfn.SWITCH($C11,"Plan 1600",25*12/26,"Plan 1400",20*12/26,"Plan 1200",15*12/26,"Plan 1000",2*12/26,"")} -> 9.2307692 | H11: =VLOOKUP(A11,'12.22'!A:B,2,FALSE) -> -646.15 | I11: {=_xlfn.IFS( H11=-738.46,"Plan 1600", H11=-646.15,"Plan 1400", H11=-553.85,"Plan 1200", H11=-461.54,"Plan 1000" )} -> Plan 1400 | J11: {=_xlfn.SWITCH($I11,"Plan 1600",15*12/26,"Plan 1400",10*12/26,"Plan 1200",5*12/26,"Plan 1000",1.5*12/26,"")} -> 4.6153846 | K11: {=_xlfn.SWITCH($I11,"Plan 1600",97*12/26,"Plan 1400",78*12/26,"Plan 1200",60*12/26,"Plan 1000",25*12/26,"")} -> 36 | L11: {=_xlfn.SWITCH($I11,"Plan 1600",25*12/26,"Plan 1400",20*12/26,"Plan 1200",15*12/26,"Plan 1000",2*12/26,"")} -> 9.2307692
A12: 616-44-6170 | B12: =VLOOKUP(A12,'12.5'!A:B,2,FALSE) -> -646.15 | C12: {=_xlfn.IFS( B12=-738.46,"Plan 1600", B12=-646.15,"Plan 1400", B12=-553.85,"Plan 1200", B12=-461.54,"Plan 1000" )} -> Plan 1400 | D12: {=_xlfn.SWITCH($C12,"Plan 1600",15*12/26,"Plan 1400",10*12/26,"Plan 1200",5*12/26,"Plan 1000",1.5*12/26,"")} -> 4.6153846 | E12: {=_xlfn.SWITCH($C12,"Plan 1600",97*12/26,"Plan 1400",78*12/26,"Plan 1200",60*12/26,"Plan 1000",25*12/26,"")} -> 36 | F12: {=_xlfn.SWITCH($C12,"Plan 1600",25*12/26,"Plan 1400",20*12/26,"Plan 1200",15*12/26,"Plan 1000",2*12/26,"")} -> 9.2307692 | H12: =VLOOKUP(A12,'12.22'!A:B,2,FALSE) -> -646.15 | I12: {=_xlfn.IFS( H12=-738.46,"Plan 1600", H12=-646.15,"Plan 1400", H12=-553.85,"Plan 1200", H12=-461.54,"Plan 1000" )} -> Plan 1400 | J12: {=_xlfn.SWITCH($I12,"Plan 1600",15*12/26,"Plan 1400",10*12/26,"Plan 1200",5*12/26,"Plan 1000",1.5*12/26,"")} -> 4.6153846 | K12: {=_xlfn.SWITCH($I12,"Plan 1600",97*12/26,"Plan 1400",78*12/26,"Plan 1200",60*12/26,"Plan 1000",25*12/26,"")} -> 36 | L12: {=_xlfn.SWITCH($I12,"Plan 1600",25*12/26,"Plan 1400",20*12/26,"Plan 1200",15*12/26,"Plan 1000",2*12/26,"")} -> 9.2307692
A13: 578-04-3439 | B13: =VLOOKUP(A13,'12.5'!A:B,2,FALSE) -> -646.15 | C13: {=_xlfn.IFS( B13=-738.46,"Plan 1600", B13=-646.15,"Plan 1400", B13=-553.85,"Plan 1200", B13=-461.54,"Plan 1000" )} -> Plan 1400 | D13: {=_xlfn.SWITCH($C13,"Plan 1600",15*12/26,"Plan 1400",10*12/26,"Plan 1200",5*12/26,"Plan 1000",1.5*12/26,"")} -> 4.6153846 | E13: {=_xlfn.SWITCH($C13,"Plan 1600",97*12/26,"Plan 1400",78*12/26,"Plan 1200",60*12/26,"Plan 1000",25*12/26,"")} -> 36 | F13: {=_xlfn.SWITCH($C13,"Plan 1600",25*12/26,"Plan 1400",20*12/26,"Plan 1200",15*12/26,"Plan 1000",2*12/26,"")} -> 9.2307692 | H13: =VLOOKUP(A13,'12.22'!A:B,2,FALSE) -> -646.15 | I13: {=_xlfn.IFS( H13=-738.46,"Plan 1600", H13=-646.15,"Plan 1400", H13=-553.85,"Plan 1200", H13=-461.54,"Plan 1000" )} -> Plan 1400 | J13: {=_xlfn.SWITCH($I13,"Plan 1600",15*12/26,"Plan 1400",10*12/26,"Plan 1200",5*12/26,"Plan 1000",1.5*12/26,"")} -> 4.6153846 | K13: {=_xlfn.SWITCH($I13,"Plan 1600",97*12/26,"Plan 1400",78*12/26,"Plan 1200",60*12/26,"Plan 1000",25*12/26,"")} -> 36 | L13: {=_xlfn.SWITCH($I13,"Plan 1600",25*12/26,"Plan 1400",20*12/26,"Plan 1200",15*12/26,"Plan 1000",2*12/26,"")} -> 9.2307692
A14: 089-70-7618 | B14: =VLOOKUP(A14,'12.5'!A:B,2,FALSE) -> -646.15 | C14: {=_xlfn.IFS( B14=-738.46,"Plan 1600", B14=-646.15,"Plan 1400", B14=-553.85,"Plan 1200", B14=-461.54,"Plan 1000" )} -> Plan 1400 | D14: {=_xlfn.SWITCH($C14,"Plan 1600",15*12/26,"Plan 1400",10*12/26,"Plan 1200",5*12/26,"Plan 1000",1.5*12/26,"")} -> 4.6153846 | E14: {=_xlfn.SWITCH($C14,"Plan 1600",97*12/26,"Plan 1400",78*12/26,"Plan 1200",60*12/26,"Plan 1000",25*12/26,"")} -> 36 | F14: {=_xlfn.SWITCH($C14,"Plan 1600",25*12/26,"Plan 1400",20*12/26,"Plan 1200",15*12/26,"Plan 1000",2*12/26,"")} -> 9.2307692 | H14: =VLOOKUP(A14,'12.22'!A:B,2,FALSE) -> -461.54 | I14: {=_xlfn.IFS( H14=-738.46,"Plan 1600", H14=-646.15,"Plan 1400", H14=-553.85,"Plan 1200", H14=-461.54,"Plan 1000" )} -> Plan 1000 | J14: {=_xlfn.SWITCH($I14,"Plan 1600",15*12/26,"Plan 1400",10*12/26,"Plan 1200",5*12/26,"Plan 1000",1.5*12/26,"")} -> 0.69230769 | K14: {=_xlfn.SWITCH($I14,"Plan 1600",97*12/26,"Plan 1400",78*12/26,"Plan 1200",60*12/26,"Plan 1000",25*12/26,"")} -> 11.538462 | L14: {=_xlfn.SWITCH($I14,"Plan 1600",25*12/26,"Plan 1400",20*12/26,"Plan 1200",15*12/26,"Plan 1000",2*12/26,"")} -> 0.92307692
A15: 594-67-7039 | B15: =VLOOKUP(A15,'12.5'!A:B,2,FALSE) -> -553.85 | C15: {=_xlfn.IFS( B15=-738.46,"Plan 1600", B15=-646.15,"Plan 1400", B15=-553.85,"Plan 1200", B15=-461.54,"Plan 1000" )} -> Plan 1200 | D15: {=_xlfn.SWITCH($C15,"Plan 1600",15*12/26,"Plan 1400",10*12/26,"Plan 1200",5*12/26,"Plan 1000",1.5*12/26,"")} -> 2.3076923 | E15: {=_xlfn.SWITCH($C15,"Plan 1600",97*12/26,"Plan 1400",78*12/26,"Plan 1200",60*12/26,"Plan 1000",25*12/26,"")} -> 27.692308 | F15: {=_xlfn.SWITCH($C15,"Plan 1600",25*12/26,"Plan 1400",20*12/26,"Plan 1200",15*12/26,"Plan 1000",2*12/26,"")} -> 6.9230769 | H15: =VLOOKUP(A15,'12.22'!A:B,2,FALSE) -> -461.54 | I15: {=_xlfn.IFS( H15=-738.46,"Plan 1600", H15=-646.15,"Plan 1400", H15=-553.85,"Plan 1200", H15=-461.54,"Plan 1000" )} -> Plan 1000 | J15: {=_xlfn.SWITCH($I15,"Plan 1600",15*12/26,"Plan 1400",10*12/26,"Plan 1200",5*12/26,"Plan 1000",1.5*12/26,"")} -> 0.69230769 | K15: {=_xlfn.SWITCH($I15,"Plan 1600",97*12/26,"Plan 1400",78*12/26,"Plan 1200",60*12/26,"Plan 1000",25*12/26,"")} -> 11.538462 | L15: {=_xlfn.SWITCH($I15,"Plan 1600",25*12/26,"Plan 1400",20*12/26,"Plan 1200",15*12/26,"Plan 1000",2*12/26,"")} -> 0.92307692
A16: 336-99-3624 | B16: =VLOOKUP(A16,'12.5'!A:B,2,FALSE) -> -553.85 | C16: {=_xlfn.IFS( B16=-738.46,"Plan 1600", B16=-646.15,"Plan 1400", B16=-553.85,"Plan 1200", B16=-461.54,"Plan 1000" )} -> Plan 1200 | D16: {=_xlfn.SWITCH($C16,"Plan 1600",15*12/26,"Plan 1400",10*12/26,"Plan 1200",5*12/26,"Plan 1000",1.5*12/26,"")} -> 2.3076923 | E16: {=_xlfn.SWITCH($C16,"Plan 1600",97*12/26,"Plan 1400",78*12/26,"Plan 1200",60*12/26,"Plan 1000",25*12/26,"")} -> 27.692308 | F16: {=_xlfn.SWITCH($C16,"Plan 1600",25*12/26,"Plan 1400",20*12/26,"Plan 1200",15*12/26,"Plan 1000",2*12/26,"")} -> 6.9230769 | H16: =VLOOKUP(A16,'12.22'!A:B,2,FALSE) -> -553.85 | I16: {=_xlfn.IFS( H16=-738.46,"Plan 1600", H16=-646.15,"Plan 1400", H16=-553.85,"Plan 1200", H16=-461.54,"Plan 1000" )} -> Plan 1200 | J16: {=_xlfn.SWITCH($I16,"Plan 1600",15*12/26,"Plan 1400",10*12/26,"Plan 1200",5*12/26,"Plan 1000",1.5*12/26,"")} -> 2.3076923 | K16: {=_xlfn.SWITCH($I16,"Plan 1600",97*12/26,"Plan 1400",78*12/26,"Plan 1200",60*12/26,"Plan 1000",25*12/26,"")} -> 27.692308 | L16: {=_xlfn.SWITCH($I16,"Plan 1600",25*12/26,"Plan 1400",20*12/26,"Plan 1200",15*12/26,"Plan 1000",2*12/26,"")} -> 6.9230769
A17: 862-84-8152 | B17: =VLOOKUP(A17,'12.5'!A:B,2,FALSE) -> -553.85 | C17: {=_xlfn.IFS( B17=-738.46,"Plan 1600", B17=-646.15,"Plan 1400", B17=-553.85,"Plan 1200", B17=-461.54,"Plan 1000" )} -> Plan 1200 | D17: {=_xlfn.SWITCH($C17,"Plan 1600",15*12/26,"Plan 1400",10*12/26,"Plan 1200",5*12/26,"Plan 1000",1.5*12/26,"")} -> 2.3076923 | E17: {=_xlfn.SWITCH($C17,"Plan 1600",97*12/26,"Plan 1400",78*12/26,"Plan 1200",60*12/26,"Plan 1000",25*12/26,"")} -> 27.692308 | F17: {=_xlfn.SWITCH($C17,"Plan 1600",25*12/26,"Plan 1400",20*12/26,"Plan 1200",15*12/26,"Plan 1000",2*12/26,"")} -> 6.9230769 | H17: =VLOOKUP(A17,'12.22'!A:B,2,FALSE) -> -553.85 | I17: {=_xlfn.IFS( H17=-738.46,"Plan 1600", H17=-646.15,"Plan 1400", H17=-553.85,"Plan 1200", H17=-461.54,"Plan 1000" )} -> Plan 1200 | J17: {=_xlfn.SWITCH($I17,"Plan 1600",15*12/26,"Plan 1400",10*12/26,"Plan 1200",5*12/26,"Plan 1000",1.5*12/26,"")} -> 2.3076923 | K17: {=_xlfn.SWITCH($I17,"Plan 1600",97*12/26,"Plan 1400",78*12/26,"Plan 1200",60*12/26,"Plan 1000",25*12/26,"")} -> 27.692308 | L17: {=_xlfn.SWITCH($I17,"Plan 1600",25*12/26,"Plan 1400",20*12/26,"Plan 1200",15*12/26,"Plan 1000",2*12/26,"")} -> 6.9230769
A18: 078-70-3980 | B18: =VLOOKUP(A18,'12.5'!A:B,2,FALSE) -> -553.85 | C18: {=_xlfn.IFS( B18=-738.46,"Plan 1600", B18=-646.15,"Plan 1400", B18=-553.85,"Plan 1200", B18=-461.54,"Plan 1000" )} -> Plan 1200 | D18: {=_xlfn.SWITCH($C18,"Plan 1600",15*12/26,"Plan 1400",10*12/26,"Plan 1200",5*12/26,"Plan 1000",1.5*12/26,"")} -> 2.3076923 | E18: {=_xlfn.SWITCH($C18,"Plan 1600",97*12/26,"Plan 1400",78*12/26,"Plan 1200",60*12/26,"Plan 1000",25*12/26,"")} -> 27.692308 | F18: {=_xlfn.SWITCH($C18,"Plan 1600",25*12/26,"Plan 1400",20*12/26,"Plan 1200",15*12/26,"Plan 1000",2*12/26,"")} -> 6.9230769 | H18: =VLOOKUP(A18,'12.22'!A:B,2,FALSE) -> -553.85 | I18: {=_xlfn.IFS( H18=-738.46,"Plan 1600", H18=-646.15,"Plan 1400", H18=-553.85,"Plan 1200", H18=-461.54,"Plan 1000" )} -> Plan 1200 | J18: {=_xlfn.SWITCH($I18,"Plan 1600",15*12/26,"Plan 1400",10*12/26,"Plan 1200",5*12/26,"Plan 1000",1.5*12/26,"")} -> 2.3076923 | K18: {=_xlfn.SWITCH($I18,"Plan 1600",97*12/26,"Plan 1400",78*12/26,"Plan 1200",60*12/26,"Plan 1000",25*12/26,"")} -> 27.692308 | L18: {=_xlfn.SWITCH($I18,"Plan 1600",25*12/26,"Plan 1400",20*12/26,"Plan 1200",15*12/26,"Plan 1000",2*12/26,"")} -> 6.9230769
A19: 644-92-3340 | B19: =VLOOKUP(A19,'12.5'!A:B,2,FALSE) -> -553.85 | C19: {=_xlfn.IFS( B19=-738.46,"Plan 1600", B19=-646.15,"Plan 1400", B19=-553.85,"Plan 1200", B19=-461.54,"Plan 1000" )} -> Plan 1200 | D19: {=_xlfn.SWITCH($C19,"Plan 1600",15*12/26,"Plan 1400",10*12/26,"Plan 1200",5*12/26,"Plan 1000",1.5*12/26,"")} -> 2.3076923 | E19: {=_xlfn.SWITCH($C19,"Plan 1600",97*12/26,"Plan 1400",78*12/26,"Plan 1200",60*12/26,"Plan 1000",25*12/26,"")} -> 27.692308 | F19: {=_xlfn.SWITCH($C19,"Plan 1600",25*12/26,"Plan 1400",20*12/26,"Plan 1200",15*12/26,"Plan 1000",2*12/26,"")} -> 6.9230769 | H19: =VLOOKUP(A19,'12.22'!A:B,2,FALSE) -> -646.15 | I19: {=_xlfn.IFS( H19=-738.46,"Plan 1600", H19=-646.15,"Plan 1400", H19=-553.85,"Plan 1200", H19=-461.54,"Plan 1000" )} -> Plan 1400 | J19: {=_xlfn.SWITCH($I19,"Plan 1600",15*12/26,"Plan 1400",10*12/26,"Plan 1200",5*12/26,"Plan 1000",1.5*12/26,"")} -> 4.6153846 | K19: {=_xlfn.SWITCH($I19,"Plan 1600",97*12/26,"Plan 1400",78*12/26,"Plan 1200",60*12/26,"Plan 1000",25*12/26,"")} -> 36 | L19: {=_xlfn.SWITCH($I19,"Plan 1600",25*12/26,"Plan 1400",20*12/26,"Plan 1200",15*12/26,"Plan 1000",2*12/26,"")} -> 9.2307692
... A47: 684-12-7500 | B47: =VLOOKUP(A47,'12.5'!A:B,2,FALSE) -> -461.54 | C47: {=_xlfn.IFS( B47=-738.46,"Plan 1600", B47=-646.15,"Plan 1400", B47=-553.85,"Plan 1200", B47=-461.54,"Plan 1000" )} -> Plan 1000 | D47: {=_xlfn.SWITCH($C47,"Plan 1600",15*12/26,"Plan 1400",10*12/26,"Plan 1200",5*12/26,"Plan 1000",1.5*12/26,"")} -> 0.69230769 | E47: {=_xlfn.SWITCH($C47,"Plan 1600",97*12/26,"Plan 1400",78*12/26,"Plan 1200",60*12/26,"Plan 1000",25*12/26,"")} -> 11.538462 | F47: {=_xlfn.SWITCH($C47,"Plan 1600",25*12/26,"Plan 1400",20*12/26,"Plan 1200",15*12/26,"Plan 1000",2*12/26,"")} -> 0.92307692 | H47: =VLOOKUP(A47,'12.22'!A:B,2,FALSE) -> -461.54 | I47: {=_xlfn.IFS( H47=-738.46,"Plan 1600", H47=-646.15,"Plan 1400", H47=-553.85,"Plan 1200", H47=-461.54,"Plan 1000" )} -> Plan 1000 | J47: {=_xlfn.SWITCH($I47,"Plan 1600",15*12/26,"Plan 1400",10*12/26,"Plan 1200",5*12/26,"Plan 1000",1.5*12/26,"")} -> 0.69230769 | K47: {=_xlfn.SWITCH($I47,"Plan 1600",97*12/26,"Plan 1400",78*12/26,"Plan 1200",60*12/26,"Plan 1000",25*12/26,"")} -> 11.538462 | L47: {=_xlfn.SWITCH($I47,"Plan 1600",25*12/26,"Plan 1400",20*12/26,"Plan 1200",15*12/26,"Plan 1000",2*12/26,"")} -> 0.92307692
D48: =SUM(D2:D47) -> 102.46154 | E48: =SUM(E2:E47) -> 973.38462 | F48: =SUM(F2:F47) -> 192 | J48: =SUM(J2:J47) -> 101.53846 | K48: =SUM(K2:K47) -> 949.84615 | L48: =SUM(L2:L47) -> 182.30769

Sheet Unpaid
A1: Number | B1: PPC125
A2: 581-79-1716 | B2: =VLOOKUP(A2,'12.5'!A:B,2,FALSE) -> -461.54 | C2: {=_xlfn.IFS( B2=-738.46,"Plan 1600", B2=-646.15,"Plan 1400", B2=-553.85,"Plan 1200", B2=-461.54,"Plan 1000" )} -> Plan 1000 | D2: {=_xlfn.SWITCH($C2,"Plan 1600",15*12/26,"Plan 1400",10*12/26,"Plan 1200",5*12/26,"Plan 1000",1.5*12/26,"")} -> 0.69230769 | E2: {=_xlfn.SWITCH($C2,"Plan 1600",97*12/26,"Plan 1400",78*12/26,"Plan 1200",60*12/26,"Plan 1000",25*12/26,"")} -> 11.538462 | F2: {=_xlfn.SWITCH($C2,"Plan 1600",25*12/26,"Plan 1400",20*12/26,"Plan 1200",15*12/26,"Plan 1000",2*12/26,"")} -> 0.92307692 | H2: =VLOOKUP(A2,'12.22'!A:B,2,FALSE) -> #N/A | I2: {=_xlfn.IFS( H2=-738.46,"Plan 1600", B2=-646.15,"Plan 1400", B2=-553.85,"Plan 1200", B2=-461.54,"Plan 1000" )} -> #N/A | J2: {=_xlfn.SWITCH($I2,"Plan 1600",15*12/26,"Plan 1400",10*12/26,"Plan 1200",5*12/26,"Plan 1000",1.5*12/26,"")} -> #N/A | K2: {=_xlfn.SWITCH($I2,"Plan 1600",97*12/26,"Plan 1400",78*12/26,"Plan 1200",60*12/26,"Plan 1000",25*12/26,"")} -> #N/A | L2: {=_xlfn.SWITCH($I2,"Plan 1600",25*12/26,"Plan 1400",20*12/26,"Plan 1200",15*12/26,"Plan 1000",2*12/26,"")} -> #N/A
A3: 594-08-9837 | B3: =VLOOKUP(A3,'12.5'!A:B,2,FALSE) -> 0 | C3: {=_xlfn.IFS( B3=-738.46,"Plan 1600", B3=-646.15,"Plan 1400", B3=-553.85,"Plan 1200", B3=-461.54,"Plan 1000" )} -> #N/A | D3: {=_xlfn.SWITCH($C3,"Plan 1600",15*12/26,"Plan 1400",10*12/26,"Plan 1200",5*12/26,"Plan 1000",1.5*12/26,"")} -> #N/A | E3: {=_xlfn.SWITCH($C3,"Plan 1600",97*12/26,"Plan 1400",78*12/26,"Plan 1200",60*12/26,"Plan 1000",25*12/26,"")} -> #N/A | F3: {=_xlfn.SWITCH($C3,"Plan 1600",25*12/26,"Plan 1400",20*12/26,"Plan 1200",15*12/26,"Plan 1000",2*12/26,"")} -> #N/A | H3: =VLOOKUP(A3,'12.22'!A:B,2,FALSE) -> 0 | I3: {=_xlfn.IFS( H3=-738.46,"Plan 1600", B3=-646.15,"Plan 1400", B3=-553.85,"Plan 1200", B3=-461.54,"Plan 1000" )} -> #N/A | J3: {=_xlfn.SWITCH($I3,"Plan 1600",15*12/26,"Plan 1400",10*12/26,"Plan 1200",5*12/26,"Plan 1000",1.5*12/26,"")} -> #N/A | K3: {=_xlfn.SWITCH($I3,"Plan 1600",97*12/26,"Plan 1400",78*12/26,"Plan 1200",60*12/26,"Plan 1000",25*12/26,"")} -> #N/A | L3: {=_xlfn.SWITCH($I3,"Plan 1600",25*12/26,"Plan 1400",20*12/26,"Plan 1200",15*12/26,"Plan 1000",2*12/26,"")} -> #N/A
A4: 122-64-4836 | B4: =VLOOKUP(A4,'12.5'!A:B,2,FALSE) -> 0 | C4: {=_xlfn.IFS( B4=-738.46,"Plan 1600", B4=-646.15,"Plan 1400", B4=-553.85,"Plan 1200", B4=-461.54,"Plan 1000" )} -> #N/A | D4: {=_xlfn.SWITCH($C4,"Plan 1600",15*12/26,"Plan 1400",10*12/26,"Plan 1200",5*12/26,"Plan 1000",1.5*12/26,"")} -> #N/A | E4: {=_xlfn.SWITCH($C4,"Plan 1600",97*12/26,"Plan 1400",78*12/26,"Plan 1200",60*12/26,"Plan 1000",25*12/26,"")} -> #N/A | F4: {=_xlfn.SWITCH($C4,"Plan 1600",25*12/26,"Plan 1400",20*12/26,"Plan 1200",15*12/26,"Plan 1000",2*12/26,"")} -> #N/A | H4: =VLOOKUP(A4,'12.22'!A:B,2,FALSE) -> 0 | I4: {=_xlfn.IFS( H4=-738.46,"Plan 1600", B4=-646.15,"Plan 1400", B4=-553.85,"Plan 1200", B4=-461.54,"Plan 1000" )} -> #N/A | J4: {=_xlfn.SWITCH($I4,"Plan 1600",15*12/26,"Plan 1400",10*12/26,"Plan 1200",5*12/26,"Plan 1000",1.5*12/26,"")} -> #N/A | K4: {=_xlfn.SWITCH($I4,"Plan 1600",97*12/26,"Plan 1400",78*12/26,"Plan 1200",60*12/26,"Plan 1000",25*12/26,"")} -> #N/A | L4: {=_xlfn.SWITCH($I4,"Plan 1600",25*12/26,"Plan 1400",20*12/26,"Plan 1200",15*12/26,"Plan 1000",2*12/26,"")} -> #N/A
A5: 262-39-5517 | B5: =VLOOKUP(A5,'12.5'!A:B,2,FALSE) -> 0 | C5: {=_xlfn.IFS( B5=-738.46,"Plan 1600", B5=-646.15,"Plan 1400", B5=-553.85,"Plan 1200", B5=-461.54,"Plan 1000" )} -> #N/A | D5: {=_xlfn.SWITCH($C5,"Plan 1600",15*12/26,"Plan 1400",10*12/26,"Plan 1200",5*12/26,"Plan 1000",1.5*12/26,"")} -> #N/A | E5: {=_xlfn.SWITCH($C5,"Plan 1600",97*12/26,"Plan 1400",78*12/26,"Plan 1200",60*12/26,"Plan 1000",25*12/26,"")} -> #N/A | F5: {=_xlfn.SWITCH($C5,"Plan 1600",25*12/26,"Plan 1400",20*12/26,"Plan 1200",15*12/26,"Plan 1000",2*12/26,"")} -> #N/A | H5: =VLOOKUP(A5,'12.22'!A:B,2,FALSE) -> -461.54 | I5: {=_xlfn.IFS( H5=-738.46,"Plan 1600", B5=-646.15,"Plan 1400", B5=-553.85,"Plan 1200", B5=-461.54,"Plan 1000" )} -> #N/A | J5: {=_xlfn.SWITCH($I5,"Plan 1600",15*12/26,"Plan 1400",10*12/26,"Plan 1200",5*12/26,"Plan 1000",1.5*12/26,"")} -> #N/A | K5: {=_xlfn.SWITCH($I5,"Plan 1600",97*12/26,"Plan 1400",78*12/26,"Plan 1200",60*12/26,"Plan 1000",25*12/26,"")} -> #N/A | L5: {=_xlfn.SWITCH($I5,"Plan 1600",25*12/26,"Plan 1400",20*12/26,"Plan 1200",15*12/26,"Plan 1000",2*12/26,"")} -> #N/A
A6: 264-95-4259 | B6: =VLOOKUP(A6,'12.5'!A:B,2,FALSE) -> 0 | C6: {=_xlfn.IFS( B6=-738.46,"Plan 1600", B6=-646.15,"Plan 1400", B6=-553.85,"Plan 1200", B6=-461.54,"Plan 1000" )} -> #N/A | D6: {=_xlfn.SWITCH($C6,"Plan 1600",15*12/26,"Plan 1400",10*12/26,"Plan 1200",5*12/26,"Plan 1000",1.5*12/26,"")} -> #N/A | E6: {=_xlfn.SWITCH($C6,"Plan 1600",97*12/26,"Plan 1400",78*12/26,"Plan 1200",60*12/26,"Plan 1000",25*12/26,"")} -> #N/A | F6: {=_xlfn.SWITCH($C6,"Plan 1600",25*12/26,"Plan 1400",20*12/26,"Plan 1200",15*12/26,"Plan 1000",2*12/26,"")} -> #N/A | H6: =VLOOKUP(A6,'12.22'!A:B,2,FALSE) -> 0 | I6: {=_xlfn.IFS( H6=-738.46,"Plan 1600", B6=-646.15,"Plan 1400", B6=-553.85,"Plan 1200", B6=-461.54,"Plan 1000" )} -> #N/A | J6: {=_xlfn.SWITCH($I6,"Plan 1600",15*12/26,"Plan 1400",10*12/26,"Plan 1200",5*12/26,"Plan 1000",1.5*12/26,"")} -> #N/A | K6: {=_xlfn.SWITCH($I6,"Plan 1600",97*12/26,"Plan 1400",78*12/26,"Plan 1200",60*12/26,"Plan 1000",25*12/26,"")} -> #N/A | L6: {=_xlfn.SWITCH($I6,"Plan 1600",25*12/26,"Plan 1400",20*12/26,"Plan 1200",15*12/26,"Plan 1000",2*12/26,"")} -> #N/A
A7: 590-29-9174 | B7: =VLOOKUP(A7,'12.5'!A:B,2,FALSE) -> 0 | C7: {=_xlfn.IFS( B7=-738.46,"Plan 1600", B7=-646.15,"Plan 1400", B7=-553.85,"Plan 1200", B7=-461.54,"Plan 1000" )} -> #N/A | D7: {=_xlfn.SWITCH($C7,"Plan 1600",15*12/26,"Plan 1400",10*12/26,"Plan 1200",5*12/26,"Plan 1000",1.5*12/26,"")} -> #N/A | E7: {=_xlfn.SWITCH($C7,"Plan 1600",97*12/26,"Plan 1400",78*12/26,"Plan 1200",60*12/26,"Plan 1000",25*12/26,"")} -> #N/A | F7: {=_xlfn.SWITCH($C7,"Plan 1600",25*12/26,"Plan 1400",20*12/26,"Plan 1200",15*12/26,"Plan 1000",2*12/26,"")} -> #N/A | H7: =VLOOKUP(A7,'12.22'!A:B,2,FALSE) -> 0 | I7: {=_xlfn.IFS( H7=-738.46,"Plan 1600", B7=-646.15,"Plan 1400", B7=-553.85,"Plan 1200", B7=-461.54,"Plan 1000" )} -> #N/A | J7: {=_xlfn.SWITCH($I7,"Plan 1600",15*12/26,"Plan 1400",10*12/26,"Plan 1200",5*12/26,"Plan 1000",1.5*12/26,"")} -> #N/A | K7: {=_xlfn.SWITCH($I7,"Plan 1600",97*12/26,"Plan 1400",78*12/26,"Plan 1200",60*12/26,"Plan 1000",25*12/26,"")} -> #N/A | L7: {=_xlfn.SWITCH($I7,"Plan 1600",25*12/26,"Plan 1400",20*12/26,"Plan 1200",15*12/26,"Plan 1000",2*12/26,"")} -> #N/A
A8: 590-01-1044 | B8: =VLOOKUP(A8,'12.5'!A:B,2,FALSE) -> 0 | C8: {=_xlfn.IFS( B8=-738.46,"Plan 1600", B8=-646.15,"Plan 1400", B8=-553.85,"Plan 1200", B8=-461.54,"Plan 1000" )} -> #N/A | D8: {=_xlfn.SWITCH($C8,"Plan 1600",15*12/26,"Plan 1400",10*12/26,"Plan 1200",5*12/26,"Plan 1000",1.5*12/26,"")} -> #N/A | E8: {=_xlfn.SWITCH($C8,"Plan 1600",97*12/26,"Plan 1400",78*12/26,"Plan 1200",60*12/26,"Plan 1000",25*12/26,"")} -> #N/A | F8: {=_xlfn.SWITCH($C8,"Plan 1600",25*12/26,"Plan 1400",20*12/26,"Plan 1200",15*12/26,"Plan 1000",2*12/26,"")} -> #N/A | H8: =VLOOKUP(A8,'12.22'!A:B,2,FALSE) -> 0 | I8: {=_xlfn.IFS( H8=-738.46,"Plan 1600", B8=-646.15,"Plan 1400", B8=-553.85,"Plan 1200", B8=-461.54,"Plan 1000" )} -> #N/A | J8: {=_xlfn.SWITCH($I8,"Plan 1600",15*12/26,"Plan 1400",10*12/26,"Plan 1200",5*12/26,"Plan 1000",1.5*12/26,"")} -> #N/A | K8: {=_xlfn.SWITCH($I8,"Plan 1600",97*12/26,"Plan 1400",78*12/26,"Plan 1200",60*12/26,"Plan 1000",25*12/26,"")} -> #N/A | L8: {=_xlfn.SWITCH($I8,"Plan 1600",25*12/26,"Plan 1400",20*12/26,"Plan 1200",15*12/26,"Plan 1000",2*12/26,"")} -> #N/A
A9: 346-72-0673 | B9: =VLOOKUP(A9,'12.5'!A:B,2,FALSE) -> 0 | C9: {=_xlfn.IFS( B9=-738.46,"Plan 1600", B9=-646.15,"Plan 1400", B9=-553.85,"Plan 1200", B9=-461.54,"Plan 1000" )} -> #N/A | D9: {=_xlfn.SWITCH($C9,"Plan 1600",15*12/26,"Plan 1400",10*12/26,"Plan 1200",5*12/26,"Plan 1000",1.5*12/26,"")} -> #N/A | E9: {=_xlfn.SWITCH($C9,"Plan 1600",97*12/26,"Plan 1400",78*12/26,"Plan 1200",60*12/26,"Plan 1000",25*12/26,"")} -> #N/A | F9: {=_xlfn.SWITCH($C9,"Plan 1600",25*12/26,"Plan 1400",20*12/26,"Plan 1200",15*12/26,"Plan 1000",2*12/26,"")} -> #N/A | H9: =VLOOKUP(A9,'12.22'!A:B,2,FALSE) -> 0 | I9: {=_xlfn.IFS( H9=-738.46,"Plan 1600", B9=-646.15,"Plan 1400", B9=-553.85,"Plan 1200", B9=-461.54,"Plan 1000" )} -> #N/A | J9: {=_xlfn.SWITCH($I9,"Plan 1600",15*12/26,"Plan 1400",10*12/26,"Plan 1200",5*12/26,"Plan 1000",1.5*12/26,"")} -> #N/A | K9: {=_xlfn.SWITCH($I9,"Plan 1600",97*12/26,"Plan 1400",78*12/26,"Plan 1200",60*12/26,"Plan 1000",25*12/26,"")} -> #N/A | L9: {=_xlfn.SWITCH($I9,"Plan 1600",25*12/26,"Plan 1400",20*12/26,"Plan 1200",15*12/26,"Plan 1000",2*12/26,"")} -> #N/A
A10: 581-97-3493 | B10: =VLOOKUP(A10,'12.5'!A:B,2,FALSE) -> 0 | C10: {=_xlfn.IFS( B10=-738.46,"Plan 1600", B10=-646.15,"Plan 1400", B10=-553.85,"Plan 1200", B10=-461.54,"Plan 1000" )} -> #N/A | D10: {=_xlfn.SWITCH($C10,"Plan 1600",15*12/26,"Plan 1400",10*12/26,"Plan 1200",5*12/26,"Plan 1000",1.5*12/26,"")} -> #N/A | E10: {=_xlfn.SWITCH($C10,"Plan 1600",97*12/26,"Plan 1400",78*12/26,"Plan 1200",60*12/26,"Plan 1000",25*12/26,"")} -> #N/A | F10: {=_xlfn.SWITCH($C10,"Plan 1600",25*12/26,"Plan 1400",20*12/26,"Plan 1200",15*12/26,"Plan 1000",2*12/26,"")} -> #N/A | H10: =VLOOKUP(A10,'12.22'!A:B,2,FALSE) -> 0 | I10: {=_xlfn.IFS( H10=-738.46,"Plan 1600", B10=-646.15,"Plan 1400", B10=-553.85,"Plan 1200", B10=-461.54,"Plan 1000" )} -> #N/A | J10: {=_xlfn.SWITCH($I10,"Plan 1600",15*12/26,"Plan 1400",10*12/26,"Plan 1200",5*12/26,"Plan 1000",1.5*12/26,"")} -> #N/A | K10: {=_xlfn.SWITCH($I10,"Plan 1600",97*12/26,"Plan 1400",78*12/26,"Plan 1200",60*12/26,"Plan 1000",25*12/26,"")} -> #N/A | L10: {=_xlfn.SWITCH($I10,"Plan 1600",25*12/26,"Plan 1400",20*12/26,"Plan 1200",15*12/26,"Plan 1000",2*12/26,"")} -> #N/A
A11: 583-77-2361 | B11: =VLOOKUP(A11,'12.5'!A:B,2,FALSE) -> 0 | C11: {=_xlfn.IFS( B11=-738.46,"Plan 1600", B11=-646.15,"Plan 1400", B11=-553.85,"Plan 1200", B11=-461.54,"Plan 1000" )} -> #N/A | D11: {=_xlfn.SWITCH($C11,"Plan 1600",15*12/26,"Plan 1400",10*12/26,"Plan 1200",5*12/26,"Plan 1000",1.5*12/26,"")} -> #N/A | E11: {=_xlfn.SWITCH($C11,"Plan 1600",97*12/26,"Plan 1400",78*12/26,"Plan 1200",60*12/26,"Plan 1000",25*12/26,"")} -> #N/A | F11: {=_xlfn.SWITCH($C11,"Plan 1600",25*12/26,"Plan 1400",20*12/26,"Plan 1200",15*12/26,"Plan 1000",2*12/26,"")} -> #N/A | H11: =VLOOKUP(A11,'12.22'!A:B,2,FALSE) -> 0 | I11: {=_xlfn.IFS( H11=-738.46,"Plan 1600", B11=-646.15,"Plan 1400", B11=-553.85,"Plan 1200", B11=-461.54,"Plan 1000" )} -> #N/A | J11: {=_xlfn.SWITCH($I11,"Plan 1600",15*12/26,"Plan 1400",10*12/26,"Plan 1200",5*12/26,"Plan 1000",1.5*12/26,"")} -> #N/A | K11: {=_xlfn.SWITCH($I11,"Plan 1600",97*12/26,"Plan 1400",78*12/26,"Plan 1200",60*12/26,"Plan 1000",25*12/26,"")} -> #N/A | L11: {=_xlfn.SWITCH($I11,"Plan 1600",25*12/26,"Plan 1400",20*12/26,"Plan 1200",15*12/26,"Plan 1000",2*12/26,"")} -> #N/A
A12: 590-93-2885 | B12: =VLOOKUP(A12,'12.5'!A:B,2,FALSE) -> 0 | C12: {=_xlfn.IFS( B12=-738.46,"Plan 1600", B12=-646.15,"Plan 1400", B12=-553.85,"Plan 1200", B12=-461.54,"Plan 1000" )} -> #N/A | D12: {=_xlfn.SWITCH($C12,"Plan 1600",15*12/26,"Plan 1400",10*12/26,"Plan 1200",5*12/26,"Plan 1000",1.5*12/26,"")} -> #N/A | E12: {=_xlfn.SWITCH($C12,"Plan 1600",97*12/26,"Plan 1400",78*12/26,"Plan 1200",60*12/26,"Plan 1000",25*12/26,"")} -> #N/A | F12: {=_xlfn.SWITCH($C12,"Plan 1600",25*12/26,"Plan 1400",20*12/26,"Plan 1200",15*12/26,"Plan 1000",2*12/26,"")} -> #N/A | H12: =VLOOKUP(A12,'12.22'!A:B,2,FALSE) -> 0 | I12: {=_xlfn.IFS( H12=-738.46,"Plan 1600", B12=-646.15,"Plan 1400", B12=-553.85,"Plan 1200", B12=-461.54,"Plan 1000" )} -> #N/A | J12: {=_xlfn.SWITCH($I12,"Plan 1600",15*12/26,"Plan 1400",10*12/26,"Plan 1200",5*12/26,"Plan 1000",1.5*12/26,"")} -> #N/A | K12: {=_xlfn.SWITCH($I12,"Plan 1600",97*12/26,"Plan 1400",78*12/26,"Plan 1200",60*12/26,"Plan 1000",25*12/26,"")} -> #N/A | L12: {=_xlfn.SWITCH($I12,"Plan 1600",25*12/26,"Plan 1400",20*12/26,"Plan 1200",15*12/26,"Plan 1000",2*12/26,"")} -> #N/A
A13: 128-67-8152 | B13: =VLOOKUP(A13,'12.5'!A:B,2,FALSE) -> 0 | C13: {=_xlfn.IFS( B13=-738.46,"Plan 1600", B13=-646.15,"Plan 1400", B13=-553.85,"Plan 1200", B13=-461.54,"Plan 1000" )} -> #N/A | D13: {=_xlfn.SWITCH($C13,"Plan 1600",15*12/26,"Plan 1400",10*12/26,"Plan 1200",5*12/26,"Plan 1000",1.5*12/26,"")} -> #N/A | E13: {=_xlfn.SWITCH($C13,"Plan 1600",97*12/26,"Plan 1400",78*12/26,"Plan 1200",60*12/26,"Plan 1000",25*12/26,"")} -> #N/A | F13: {=_xlfn.SWITCH($C13,"Plan 1600",25*12/26,"Plan 1400",20*12/26,"Plan 1200",15*12/26,"Plan 1000",2*12/26,"")} -> #N/A | H13: =VLOOKUP(A13,'12.22'!A:B,2,FALSE) -> 0 | I13: {=_xlfn.IFS( H13=-738.46,"Plan 1600", B13=-646.15,"Plan 1400", B13=-553.85,"Plan 1200", B13=-461.54,"Plan 1000" )} -> #N/A | J13: {=_xlfn.SWITCH($I13,"Plan 1600",15*12/26,"Plan 1400",10*12/26,"Plan 1200",5*12/26,"Plan 1000",1.5*12/26,"")} -> #N/A | K13: {=_xlfn.SWITCH($I13,"Plan 1600",97*12/26,"Plan 1400",78*12/26,"Plan 1200",60*12/26,"Plan 1000",25*12/26,"")} -> #N/A | L13: {=_xlfn.SWITCH($I13,"Plan 1600",25*12/26,"Plan 1400",20*12/26,"Plan 1200",15*12/26,"Plan 1000",2*12/26,"")} -> #N/A
... A31: 083-90-5014 | B31: =VLOOKUP(A31,'12.5'!A:B,2,FALSE) -> -461.54 | C31: {=_xlfn.IFS( B31=-738.46,"Plan 1600", B31=-646.15,"Plan 1400", B31=-553.85,"Plan 1200", B31=-461.54,"Plan 1000" )} -> Plan 1000 | D31: {=_xlfn.SWITCH($C31,"Plan 1600",15*12/26,"Plan 1400",10*12/26,"Plan 1200",5*12/26,"Plan 1000",1.5*12/26,"")} -> 0.69230769 | E31: {=_xlfn.SWITCH($C31,"Plan 1600",97*12/26,"Plan 1400",78*12/26,"Plan 1200",60*12/26,"Plan 1000",25*12/26,"")} -> 11.538462 | F31: {=_xlfn.SWITCH($C31,"Plan 1600",25*12/26,"Plan 1400",20*12/26,"Plan 1200",15*12/26,"Plan 1000",2*12/26,"")} -> 0.92307692 | H31: =VLOOKUP(A31,'12.22'!A:B,2,FALSE) -> 0 | I31: {=_xlfn.IFS( H31=-738.46,"Plan 1600", B31=-646.15,"Plan 1400", B31=-553.85,"Plan 1200", B31=-461.54,"Plan 1000" )} -> Plan 1000 | J31: {=_xlfn.SWITCH($I31,"Plan 1600",15*12/26,"Plan 1400",10*12/26,"Plan 1200",5*12/26,"Plan 1000",1.5*12/26,"")} -> 0.69230769 | K31: {=_xlfn.SWITCH($I31,"Plan 1600",97*12/26,"Plan 1400",78*12/26,"Plan 1200",60*12/26,"Plan 1000",25*12/26,"")} -> 11.538462 | L31: {=_xlfn.SWITCH($I31,"Plan 1600",25*12/26,"Plan 1400",20*12/26,"Plan 1200",15*12/26,"Plan 1000",2*12/26,"")} -> 0.92307692

Sheet 12.5
A1: SSN | B1: D-ppc 125
A2: 589-39-8064 | B2: -461.54
A3: 265-17-2317 | B3: -461.54
A4: 256-06-5812 | B4: -461.54
A5: 593-43-4445 | B5: -738.46
A6: 263-79-8264 | B6: -738.46
A7: 438-67-6419 | B7: -738.46
A8: 267-27-8279 | B8: -738.46
A9: 732-07-4120 | B9: -461.54
A10: 592-25-0250 | B10: -461.54
A11: 594-08-9837
A12: 122-64-4836
A13: 083-90-5014 | B13: -461.54
A14: 266-47-7175 | B14: -461.54
A15: 266-68-6434 | B15: -461.54
A16: 584-81-8792 | B16: -646.15
A17: 263-53-6471 | B17: -461.54
A18: 264-19-6050 | B18: -461.54
A19: 170-81-2820 | B19: -646.15
A20: 262-39-5517
A21: 264-95-4259
A22: 590-29-9174
A23: 590-01-1044
A24: 772-16-6558 | B24: -461.54
A25: 346-72-0673
A26: 594-67-7039 | B26: -553.85
A27: 696-60-4090 | B27: -461.54
A28: 592-81-9869 | B28: -461.54
A29: 883-77-8340 | B29: -646.15
A30: 131-44-2343 | B30: -646.15
A31: 581-79-1716 | B31: -461.54
A32: 581-97-3493
A33: 593-44-9070 | B33: -646.15
A34: 184-97-8055 | B34: -461.54
A35: 597-56-1958 | B35: -553.85
A36: 583-77-2361
A37: 616-44-6170 | B37: -646.15
A38: 590-93-2885
A39: 128-67-8152
A40: 262-55-7788 | B40: -461.54
...

Sheet 12.22
A1: SSN | B1: D-ppc 125
A2: 589-39-8064 | B2: -461.54
A3: 265-17-2317 | B3: -461.54
A4: 256-06-5812 | B4: -461.54
A5: 593-43-4445 | B5: -738.46
A6: 263-79-8264 | B6: -738.46
A7: 438-67-6419 | B7: -738.46
A8: 267-27-8279 | B8: -738.46
A9: 732-07-4120 | B9: -461.54
A10: 592-25-0250 | B10: -461.54
A11: 594-08-9837
A12: 122-64-4836
A13: 083-90-5014
A14: 266-47-7175 | B14: -461.54
A15: 589-97-7430
A16: 266-68-6434 | B16: -461.54
A17: 584-81-8792 | B17: -646.15
A18: 263-53-6471 | B18: -461.54
A19: 264-19-6050 | B19: -461.54
A20: 170-81-2820 | B20: -646.15
A21: 262-39-5517 | B21: -461.54
A22: 264-95-4259
A23: 590-29-9174
A24: 590-01-1044
A25: 772-16-6558 | B25: -461.54
A26: 346-72-0673
A27: 594-67-7039 | B27: -461.54
A28: 696-60-4090 | B28: -461.54
A29: 592-81-9869 | B29: -461.54
A30: 883-77-8340 | B30: -646.15
A31: 131-44-2343 | B31: -738.46
A32: 581-97-3493
A33: 593-44-9070 | B33: -646.15
A34: 184-97-8055 | B34: -461.54
A35: 597-56-1958
A36: 583-77-2361
A37: 616-44-6170 | B37: -646.15
A38: 590-93-2885
A39: 128-67-8152
A40: 262-55-7788 | B40: -461.54
...
